<?xml version="1.0"?>
<robot
  name="LOGAN">
  <link name="world"/>

  <joint name="world_to_base" type="fixed">
  <parent link="world"/>
  <child link="base_link"/>
  <origin xyz="0 0 0" rpy="0 0 0"/>
  </joint>
  <link
    name="base_link">
    <inertial>
      <origin
        xyz="-6.9389E-18 0 0.0087108"
        rpy="0 0 0" />
      <mass
        value="0.19048" />
      <inertia
        ixx="0.00022475"
        ixy="-1.4889E-20"
        ixz="1.9077E-20"
        iyy="0.00025673"
        iyz="-1.3751E-21"
        izz="0.00045057" />
    </inertial>
    <visual>
      <origin
        xyz="0 0 0"
        rpy="0 0 0" />
      <geometry>
        <mesh
          filename="file:///home/quocphu/arm6_dof_log/src/my_robot/meshes/base_link.STL" />
      </geometry>
      <material
        name="">
        <color
          rgba="0.79216 0.81961 0.93333 1" />
      </material>
    </visual>
    <collision>
      <origin
        xyz="0 0 0"
        rpy="0 0 0" />
      <geometry>
        <mesh
          filename="file:///home/quocphu/arm6_dof_log/src/my_robot/meshes/base_link.STL" />
      </geometry>
    </collision>
  </link>
  <link
    name="link1">
    <inertial>
      <origin
        xyz="0.0013689 -0.010184 0.054404"
        rpy="0 0 0" />
      <mass
        value="0.1739" />
      <inertia
        ixx="0.00029868"
        ixy="1.0877E-05"
        ixz="1.0483E-06"
        iyy="0.00021922"
        iyz="-7.7999E-06"
        izz="0.00027014" />
    </inertial>
    <visual>
      <origin
        xyz="0 0 0"
        rpy="0 0 0" />
      <geometry>
        <mesh
          filename="file:///home/quocphu/arm6_dof_log/src/my_robot/meshes/link1.STL" />
      </geometry>
      <material
        name="">
        <color
          rgba="0.79216 0.81961 0.93333 1" />
      </material>
    </visual>
    <collision>
      <origin
        xyz="0 0 0"
        rpy="0 0 0" />
      <geometry>
        <mesh
          filename="file:///home/quocphu/arm6_dof_log/src/my_robot/meshes/link1.STL" />
      </geometry>
    </collision>
  </link>
  <joint
    name="joint1"
    type="revolute">
    <origin
      xyz="0 0 0.04"
      rpy="0 0 0" />
    <parent
      link="base_link" />
    <child
      link="link1" />
    <axis
      xyz="0 0 1" />
    <limit
      lower="-3.14"
      upper="3.14"
      effort="100"
      velocity="1" />
  </joint>
  <link
    name="link2">
    <inertial>
      <origin
        xyz="-0.067796 0.037914 0.04758"
        rpy="0 0 0" />
      <mass
        value="0.22615" />
      <inertia
        ixx="0.00039984"
        ixy="0.00041152"
        ixz="-1.1102E-06"
        iyy="0.00090558"
        iyz="6.2054E-07"
        izz="0.0010785" />
    </inertial>
    <visual>
      <origin
        xyz="0 0 0"
        rpy="0 0 0" />
      <geometry>
        <mesh
          filename="file:///home/quocphu/arm6_dof_log/src/my_robot/meshes/link2.STL" />
      </geometry>
      <material
        name="">
        <color
          rgba="0.79216 0.81961 0.93333 1" />
      </material>
    </visual>
    <collision>
      <origin
        xyz="0 0 0"
        rpy="0 0 0" />
      <geometry>
        <mesh
          filename="file:///home/quocphu/arm6_dof_log/src/my_robot/meshes/link2.STL" />
      </geometry>
    </collision>
  </link>
  <joint
    name="joint2"
    type="revolute">
    <origin
      xyz="0.010657 -0.079287 0.05"
      rpy="1.5708 0 0.13361" />
    <parent
      link="link1" />
    <child
      link="link2" />
    <axis
      xyz="0 0 -1" />
    <limit
      lower="-3.14"
      upper="3.14"
      effort="100"
      velocity="1" />
  </joint>
  <link
    name="link3">
    <inertial>
      <origin
        xyz="-0.046117 0.068194 -0.047578"
        rpy="0 0 0" />
      <mass
        value="0.22613" />
      <inertia
        ixx="0.00083256"
        ixy="0.00044827"
        ixz="-7.1186E-07"
        iyy="0.00047285"
        iyz="1.0526E-06"
        izz="0.0010785" />
    </inertial>
    <visual>
      <origin
        xyz="0 0 0"
        rpy="0 0 0" />
      <geometry>
        <mesh
          filename="file:///home/quocphu/arm6_dof_log/src/my_robot/meshes/link3.STL" />
      </geometry>
      <material
        name="">
        <color
          rgba="0.79216 0.81961 0.93333 1" />
      </material>
    </visual>
    <collision>
      <origin
        xyz="0 0 0"
        rpy="0 0 0" />
      <geometry>
        <mesh
          filename="file:///home/quocphu/arm6_dof_log/src/my_robot/meshes/link3.STL" />
      </geometry>
    </collision>
  </link>
  <joint
    name="joint3"
    type="revolute">
    <origin
      xyz="-0.13965 0.078095 0"
      rpy="0 0 -0.5099" />
    <parent
      link="link2" />
    <child
      link="link3" />
    <axis
      xyz="0 0 -1" />
    <limit
      lower="-3.14"
      upper="3.14"
      effort="100"
      velocity="1" />
  </joint>
  <link
    name="link4">
    <inertial>
      <origin
        xyz="-0.0107792481088815 -0.0047375776397908 0.0353513548224389"
        rpy="0 0 0" />
      <mass
        value="0.0952840354278206" />
      <inertia
        ixx="6.50224823848732E-05"
        ixy="-2.31395323516346E-05"
        ixz="4.77455790465928E-06"
        iyy="0.00010750207329048"
        iyz="2.09827898734923E-06"
        izz="0.000110948138986023" />
    </inertial>
    <visual>
      <origin
        xyz="0 0 0"
        rpy="0 0 0" />
      <geometry>
        <mesh
          filename="file:///home/quocphu/arm6_dof_log/src/my_robot/meshes/link4.STL" />
      </geometry>
      <material
        name="">
        <color
          rgba="0.792156862745098 0.819607843137255 0.933333333333333 1" />
      </material>
    </visual>
    <collision>
      <origin
        xyz="0 0 0"
        rpy="0 0 0" />
      <geometry>
        <mesh
          filename="file:///home/quocphu/arm6_dof_log/src/my_robot/meshes/link4.STL" />
      </geometry>
    </collision>
  </link>
  <joint
    name="joint4"
    type="revolute">
    <origin
      xyz="-0.089631 0.13254 0"
      rpy="0 0 -0.97618" />
    <parent
      link="link3" />
    <child
      link="link4" />
    <axis
      xyz="0 0 1" />
    <limit
      lower="-3.14"
      upper="3.14"
      effort="100"
      velocity="1" />
  </joint>
  <link
    name="link5">
    <inertial>
      <origin
        xyz="-0.000930329749084417 0.0032417861093968 0.0345414973243044"
        rpy="0 0 0" />
      <mass
        value="0.0811467564205841" />
      <inertia
        ixx="7.25302627515444E-05"
        ixy="7.25493858121939E-06"
        ixz="4.11959557309902E-07"
        iyy="4.93305432097539E-05"
        iyz="-1.43595590793347E-06"
        izz="6.82472542369724E-05" />
    </inertial>
    <visual>
      <origin
        xyz="0 0 0"
        rpy="0 0 0" />
      <geometry>
        <mesh
          filename="file:///home/quocphu/arm6_dof_log/src/my_robot/meshes/link5.STL" />
      </geometry>
      <material
        name="">
        <color
          rgba="0.792156862745098 0.819607843137255 0.933333333333333 1" />
      </material>
    </visual>
    <collision>
      <origin
        xyz="0 0 0"
        rpy="0 0 0" />
      <geometry>
        <mesh
          filename="file:///home/quocphu/arm6_dof_log/src/my_robot/meshes/link5.STL" />
      </geometry>
    </collision>
  </link>
  <joint
    name="joint5"
    type="revolute">
    <origin
      xyz="-0.064084 -0.028165 0.04"
      rpy="1.5708 0.15189 -1.1567" />
    <parent
      link="link4" />
    <child
      link="link5" />
    <axis
      xyz="0 0 1" />
    <limit
      lower="-3.14"
      upper="3.14"
      effort="100"
      velocity="1" />
  </joint>
  <link
    name="link6">
    <inertial>
      <origin
        xyz="-1.38777878078145E-15 9.93649607039515E-15 0.02391494446307"
        rpy="0 0 0" />
      <mass
        value="0.0503373028998775" />
      <inertia
        ixx="1.43265770837539E-05"
        ixy="-1.95876369052557E-21"
        ixz="-2.32934060494933E-21"
        iyy="1.4326577083754E-05"
        iyz="6.72332401883101E-21"
        izz="1.78945903377802E-05" />
    </inertial>
    <visual>
      <origin
        xyz="0 0 0"
        rpy="0 0 0" />
      <geometry>
        <mesh
          filename="file:///home/quocphu/arm6_dof_log/src/my_robot/meshes/link6.STL" />
      </geometry>
      <material
        name="">
        <color
          rgba="0.792156862745098 0.819607843137255 0.933333333333333 1" />
      </material>
    </visual>
    <collision>
      <origin
        xyz="0 0 0"
        rpy="0 0 0" />
      <geometry>
        <mesh
          filename="file:///home/quocphu/arm6_dof_log/src/my_robot/meshes/link6.STL" />
      </geometry>
    </collision>
  </link>
  <joint
    name="joint6"
    type="revolute">
    <origin
      xyz="-0.013792 0.04806 0.04"
      rpy="-1.5708 -0.51065 0.27946" />
    <parent
      link="link5" />
    <child
      link="link6" />
    <axis
      xyz="0 0 -1" />
    <limit
      lower="-3.14"
      upper="3.14"
      effort="100"
      velocity="1" />
  </joint>
  <link
    name="ee_link">
    <inertial>
      <origin
        xyz="2.77555756156289E-17 -5.55111512312578E-17 -0.01"
        rpy="0 0 0" />
      <mass
        value="0.00353429173528852" />
      <inertia
        ixx="1.67510702037112E-07"
        ixy="-4.3426982159034E-24"
        ixz="6.1211365328924E-23"
        iyy="1.67510702037112E-07"
        iyz="6.90695811481778E-23"
        izz="9.94019550549896E-08" />
    </inertial>
    <visual>
      <origin
        xyz="0 0 0"
        rpy="0 0 0" />
      <geometry>
        <mesh
          filename="file:///home/quocphu/arm6_dof_log/src/my_robot/meshes/ee_link.STL" />
      </geometry>
      <material
        name="">
        <color
          rgba="0.00784313725490196 0.23921568627451 0.823529411764706 1" />
      </material>
    </visual>
    <collision>
      <origin
        xyz="0 0 0"
        rpy="0 0 0" />
      <geometry>
        <mesh
          filename="file:///home/quocphu/arm6_dof_log/src/my_robot/meshes/ee_link.STL" />
      </geometry>
    </collision>
  </link>
  <joint
    name="dummy_fix_ee"
    type="fixed">
    <origin
      xyz="0 0 0.06"
      rpy="0 0 -3.1416" />
    <parent
      link="link6" />
    <child
      link="ee_link" />
    <axis
      xyz="0 0 1" />
    <limit
      lower="0"
      upper="0"
      effort="0"
      velocity="0" />
  </joint>

<ros2_control name="GazeboSystem" type="system">
  <hardware>
    <plugin>gazebo_ros2_control/GazeboSystem</plugin>
  </hardware>
  
  <joint name="joint1">
    <command_interface name="position">
      <param name="min">-3.14</param>
      <param name="max">3.14</param>
    </command_interface>
    <state_interface name="position"/>
    <state_interface name="velocity"/>
  </joint>
  
  <joint name="joint2">
    <command_interface name="position">
      <param name="min">-3.14</param>
      <param name="max">3.14</param>
    </command_interface>
    <state_interface name="position"/>
    <state_interface name="velocity"/>
  </joint>
  
  <joint name="joint3">
    <command_interface name="position">
      <param name="min">-3.14</param>
      <param name="max">3.14</param>
    </command_interface>
    <state_interface name="position"/>
    <state_interface name="velocity"/>
  </joint>
  
  <joint name="joint4">
    <command_interface name="position">
      <param name="min">-3.14</param>
      <param name="max">3.14</param>
    </command_interface>
    <state_interface name="position"/>
    <state_interface name="velocity"/>
  </joint>
  
  <joint name="joint5">
    <command_interface name="position">
      <param name="min">-3.14</param>
      <param name="max">3.14</param>
    </command_interface>
    <state_interface name="position"/>
    <state_interface name="velocity"/>
  </joint>
  
  <joint name="joint6">
    <command_interface name="position">
      <param name="min">-3.14</param>
      <param name="max">3.14</param>
    </command_interface>
    <state_interface name="position"/>
    <state_interface name="velocity"/>
  </joint>
</ros2_control>

 <gazebo>
  <plugin name="gazebo_ros2_control" filename="libgazebo_ros2_control.so">
    <robotParam>robot_description</robotParam>
    <robot_param_node>robot_state_publisher</robot_param_node>
    <controlPeriod>0.001</controlPeriod> -->
    <parameters>/home/quocphu/arm6_dof_log/src/my_robot/config/quocphu_controllers.yaml</parameters>   
  </plugin>
 </gazebo>

</robot>